
<mujoco model="jenga">

    <compiler angle="degree" coordinate="local"/>

    <option gravity="0 0 -9.81" timestep="0.002" iterations="200" solver="Newton" />

    <default>
        <geom density="650"
              margin="0.0005"
              gap="0.0005"
/>
    </default>

    <worldbody>
        <light diffuse=".5 .5 .5" pos="0 0 4" dir="0 0 -1"/>

        <geom
            type="plane"
            size="0.3 0.3 0.01"
            rgba="0.96 0.93 0.73 1"
            friction="0.8 0.001 0.0001"
        />

        <body name="hook" pos="0.15 0.05 0.16">
            <joint name="hook_slide" type="slide" axis="1 0 0" damping="2"/>

            <geom type="box"
                size="0.04 0.005 0.01"
                pos="0 0 0"
                rgba="0.1 0.1 0.9 1"
                density="2000"
                contype="0"
                conaffinity="0"/>

            <geom type="box"
                size="0.006 0.004 0.004"
                pos="-0.05 0 0"
                rgba="1 0 0 1"
                density="2000"/>
        </body>

        <body name="hook2" pos="0.15 -0.05 0.107">
            <joint name="hook_slide2" type="slide" axis="1 0 0" damping="2"/>

            <geom type="box"
                size="0.04 0.005 0.01"
                pos="0 0 0"
                rgba="0.1 0.1 0.9 1"
                density="2000"
                contype="0"
                conaffinity="0"/>

            <geom type="box"
                size="0.006 0.004 0.004"
                pos="-0.05 0 0"
                rgba="1 0 0 1"
                density="2000"/>
        </body>

        <body name="hook3" pos="0.15 0 0.107">
            <joint name="hook_slide3" type="slide" axis="1 0 0" damping="2"/>

            <geom type="box"
                size="0.04 0.005 0.01"
                pos="0 0 0"
                rgba="0.1 0.1 0.9 1"
                density="2000"
                contype="0"
                conaffinity="0"/>

            <geom type="box"
                size="0.006 0.004 0.004"
                pos="-0.05 0 0"
                rgba="1 0 0 1"
                density="2000"/>
        </body>

        
        <body name="b1_1" pos="-0.0505 0 0.0155" >
            <joint type="free"/>

            <geom
                type="box"
                size="0.025 0.076 0.015"
                rgba="0.68 0.85 0.9 1"
                friction="0.369 0.048 0.001"
            />
        </body>

        <body name="b1_2" pos="0 0 0.0155" >
            <joint type="free"/>

            <geom
                type="box"
                size="0.025 0.076 0.015"
                rgba="0.96 0.96 0.95 1"
                friction="0.284 0.023 0.001"
            />
        </body>

        <body name="b1_3" pos="0.0505 0 0.0155" >
            <joint type="free"/>

            <geom
                type="box"
                size="0.025 0.076 0.015"
                rgba="0.68 0.85 0.9 1"
                friction="0.302 0.030 0.001"
            />
        </body>

        
        <body name="b2_1" pos="0 0.0505 0.046" euler="0 0 90">
            <joint type="free"/>

            <geom
                type="box"
                size="0.025 0.076 0.015"
                rgba="0.96 0.96 0.95 1"
                friction="0.357 0.025 0.001"
            />
        </body>

        <body name="b2_2" pos="0 0 0.046" euler="0 0 90">
            <joint type="free"/>

            <geom
                type="box"
                size="0.025 0.076 0.015"
                rgba="0.68 0.85 0.9 1"
                friction="0.295 0.039 0.001"
            />
        </body>

        <body name="b2_3" pos="0 -0.0505 0.046" euler="0 0 90">
            <joint type="free"/>

            <geom
                type="box"
                size="0.025 0.076 0.015"
                rgba="0.96 0.96 0.95 1"
                friction="0.382 0.035 0.001"
            />
        </body>

        
        <body name="b3_1" pos="-0.0505 0 0.0765" >
            <joint type="free"/>

            <geom
                type="box"
                size="0.025 0.076 0.015"
                rgba="0.68 0.85 0.9 1"
                friction="0.256 0.048 0.001"
            />
        </body>

        <body name="b3_2" pos="0 0 0.0765" >
            <joint type="free"/>

            <geom
                type="box"
                size="0.025 0.076 0.015"
                rgba="0.96 0.96 0.95 1"
                friction="0.324 0.023 0.001"
            />
        </body>

        <body name="b3_3" pos="0.0505 0 0.0765" >
            <joint type="free"/>

            <geom
                type="box"
                size="0.025 0.076 0.015"
                rgba="0.68 0.85 0.9 1"
                friction="0.382 0.059 0.001"
            />
        </body>

        
        <body name="b4_1" pos="0 0.0505 0.107" euler="0 0 90">
            <joint type="free"/>

            <geom
                type="box"
                size="0.025 0.076 0.015"
                rgba="0.96 0.96 0.95 1"
                friction="0.362 0.055 0.001"
            />
        </body>

        <body name="b4_2" pos="0 0 0.107" euler="0 0 90">
            <joint type="free"/>

            <geom
                type="box"
                size="0.025 0.076 0.015"
                rgba="0.68 0.85 0.9 1"
                friction="0.262 0.046 0.001"
            />
        </body>

        <body name="b4_3" pos="0 -0.0505 0.107" euler="0 0 90">
            <joint type="free"/>

            <geom
                type="box"
                size="0.025 0.076 0.015"
                rgba="0.96 0.96 0.95 1"
                friction="0.380 0.044 0.001"
            />
        </body>

        
        <body name="b5_1" pos="-0.0505 0 0.1375" >
            <joint type="free"/>

            <geom
                type="box"
                size="0.025 0.076 0.015"
                rgba="0.68 0.85 0.9 1"
                friction="0.294 0.015 0.001"
            />
        </body>

        <body name="b5_2" pos="0 0 0.1375" >
            <joint type="free"/>

            <geom
                type="box"
                size="0.025 0.076 0.015"
                rgba="0.96 0.96 0.95 1"
                friction="0.287 0.041 0.001"
            />
        </body>

        <body name="b5_3" pos="0.0505 0 0.1375" >
            <joint type="free"/>

            <geom
                type="box"
                size="0.025 0.076 0.015"
                rgba="0.68 0.85 0.9 1"
                friction="0.383 0.058 0.001"
            />
        </body>

        
        <body name="b6_1" pos="0 0.0505 0.168" euler="0 0 90">
            <joint type="free"/>

            <geom
                type="box"
                size="0.025 0.076 0.015"
                rgba="0.96 0.96 0.95 1"
                friction="0.295 0.053 0.001"
            />
        </body>

        <body name="b6_2" pos="0 0 0.168" euler="0 0 90">
            <joint type="free"/>

            <geom
                type="box"
                size="0.025 0.076 0.015"
                rgba="0.68 0.85 0.9 1"
                friction="0.252 0.050 0.001"
            />
        </body>

        <body name="b6_3" pos="0 -0.0505 0.168" euler="0 0 90">
            <joint type="free"/>

            <geom
                type="box"
                size="0.025 0.076 0.015"
                rgba="0.96 0.96 0.95 1"
                friction="0.310 0.011 0.001"
            />
        </body>

        
        <body name="b7_1" pos="-0.0505 0 0.1985" >
            <joint type="free"/>

            <geom
                type="box"
                size="0.025 0.076 0.015"
                rgba="0.68 0.85 0.9 1"
                friction="0.344 0.030 0.001"
            />
        </body>

        <body name="b7_2" pos="0 0 0.1985" >
            <joint type="free"/>

            <geom
                type="box"
                size="0.025 0.076 0.015"
                rgba="0.96 0.96 0.95 1"
                friction="0.365 0.043 0.001"
            />
        </body>

        <body name="b7_3" pos="0.0505 0 0.1985" >
            <joint type="free"/>

            <geom
                type="box"
                size="0.025 0.076 0.015"
                rgba="0.68 0.85 0.9 1"
                friction="0.200 0.035 0.001"
            />
        </body>

        
        <body name="b8_1" pos="0 0.0505 0.229" euler="0 0 90">
            <joint type="free"/>

            <geom
                type="box"
                size="0.025 0.076 0.015"
                rgba="0.96 0.96 0.95 1"
                friction="0.374 0.022 0.001"
            />
        </body>

        <body name="b8_2" pos="0 0 0.229" euler="0 0 90">
            <joint type="free"/>

            <geom
                type="box"
                size="0.025 0.076 0.015"
                rgba="0.68 0.85 0.9 1"
                friction="0.265 0.054 0.001"
            />
        </body>

        <body name="b8_3" pos="0 -0.0505 0.229" euler="0 0 90">
            <joint type="free"/>

            <geom
                type="box"
                size="0.025 0.076 0.015"
                rgba="0.96 0.96 0.95 1"
                friction="0.238 0.038 0.001"
            />
        </body>

        
        <body name="b9_1" pos="-0.0505 0 0.2595" >
            <joint type="free"/>

            <geom
                type="box"
                size="0.025 0.076 0.015"
                rgba="0.68 0.85 0.9 1"
                friction="0.248 0.058 0.001"
            />
        </body>

        <body name="b9_2" pos="0 0 0.2595" >
            <joint type="free"/>

            <geom
                type="box"
                size="0.025 0.076 0.015"
                rgba="0.96 0.96 0.95 1"
                friction="0.361 0.032 0.001"
            />
        </body>

        <body name="b9_3" pos="0.0505 0 0.2595" >
            <joint type="free"/>

            <geom
                type="box"
                size="0.025 0.076 0.015"
                rgba="0.68 0.85 0.9 1"
                friction="0.216 0.026 0.001"
            />
        </body>

    </worldbody>

    <actuator>
        <motor joint="hook_slide" ctrlrange="-1 1" gear="5"/>
        <motor joint="hook_slide2" ctrlrange="-1 1" gear="5"/>
        <motor joint="hook_slide3" ctrlrange="-1 1" gear="5"/>
    </actuator>

</mujoco>
