
<mujoco model="jenga">

    <compiler angle="degree" coordinate="local"/>

    <option gravity="0 0 -9.81" timestep="0.002" iterations="200" solver="Newton" />

    <default>
        <geom density="650"
              margin="0.0005"
              gap="0.0005"
              solref="0.005 1"
              solimp="0.95 0.99 0.001" />
    </default>

    <worldbody>
        <light diffuse=".5 .5 .5" pos="0 0 4" dir="0 0 -1"/>

        <geom
            type="plane"
            size="0.3 0.3 0.01"
            rgba="0.96 0.93 0.73 1"
            friction="0.3 0.001 0.0001"
        />

        <body name="hook" pos="0.15 0.05 0.16">
            <joint name="hook_slide" type="slide" axis="1 0 0"/>

            <geom type="box"
                size="0.04 0.005 0.01"
                pos="0 0 0"
                rgba="0.1 0.1 0.9 1"
                density="2000"/>

            <geom type="box"
                size="0.01 0.01 0.01"
                pos="-0.05 0 0"
                rgba="1 0 0 1"
                density="2000"/>
        </body>

        
        <body name="b1_1" pos="-0.0505 0 0.0155" >
            <joint type="free"/>

            <geom
                type="box"
                size="0.025 0.076 0.015"
                rgba="0.68 0.85 0.9 1"
                friction="0.453 0.427 0.001"
            />
        </body>

        <body name="b1_2" pos="0 0 0.0155" >
            <joint type="free"/>

            <geom
                type="box"
                size="0.025 0.076 0.015"
                rgba="0.96 0.96 0.95 1"
                friction="0.326 0.278 0.001"
            />
        </body>

        <body name="b1_3" pos="0.0505 0 0.0155" >
            <joint type="free"/>

            <geom
                type="box"
                size="0.025 0.076 0.015"
                rgba="0.68 0.85 0.9 1"
                friction="0.353 0.321 0.001"
            />
        </body>

        
        <body name="b2_1" pos="0 0.0505 0.046" euler="0 0 90">
            <joint type="free"/>

            <geom
                type="box"
                size="0.025 0.076 0.015"
                rgba="0.96 0.96 0.95 1"
                friction="0.435 0.291 0.001"
            />
        </body>

        <body name="b2_2" pos="0 0 0.046" euler="0 0 90">
            <joint type="free"/>

            <geom
                type="box"
                size="0.025 0.076 0.015"
                rgba="0.68 0.85 0.9 1"
                friction="0.343 0.375 0.001"
            />
        </body>

        <body name="b2_3" pos="0 -0.0505 0.046" euler="0 0 90">
            <joint type="free"/>

            <geom
                type="box"
                size="0.025 0.076 0.015"
                rgba="0.96 0.96 0.95 1"
                friction="0.472 0.351 0.001"
            />
        </body>

        
        <body name="b3_1" pos="-0.0505 0 0.0765" >
            <joint type="free"/>

            <geom
                type="box"
                size="0.025 0.076 0.015"
                rgba="0.68 0.85 0.9 1"
                friction="0.285 0.427 0.001"
            />
        </body>

        <body name="b3_2" pos="0 0 0.0765" >
            <joint type="free"/>

            <geom
                type="box"
                size="0.025 0.076 0.015"
                rgba="0.96 0.96 0.95 1"
                friction="0.386 0.275 0.001"
            />
        </body>

        <body name="b3_3" pos="0.0505 0 0.0765" >
            <joint type="free"/>

            <geom
                type="box"
                size="0.025 0.076 0.015"
                rgba="0.68 0.85 0.9 1"
                friction="0.473 0.495 0.001"
            />
        </body>

        
        <body name="b4_1" pos="0 0.0505 0.107" euler="0 0 90">
            <joint type="free"/>

            <geom
                type="box"
                size="0.025 0.076 0.015"
                rgba="0.96 0.96 0.95 1"
                friction="0.443 0.471 0.001"
            />
        </body>

        <body name="b4_2" pos="0 0 0.107" euler="0 0 90">
            <joint type="free"/>

            <geom
                type="box"
                size="0.025 0.076 0.015"
                rgba="0.68 0.85 0.9 1"
                friction="0.293 0.419 0.001"
            />
        </body>

        <body name="b4_3" pos="0 -0.0505 0.107" euler="0 0 90">
            <joint type="free"/>

            <geom
                type="box"
                size="0.025 0.076 0.015"
                rgba="0.96 0.96 0.95 1"
                friction="0.470 0.405 0.001"
            />
        </body>

        
        <body name="b5_1" pos="-0.0505 0 0.1375" >
            <joint type="free"/>

            <geom
                type="box"
                size="0.025 0.076 0.015"
                rgba="0.68 0.85 0.9 1"
                friction="0.342 0.230 0.001"
            />
        </body>

        <body name="b5_2" pos="0 0 0.1375" >
            <joint type="free"/>

            <geom
                type="box"
                size="0.025 0.076 0.015"
                rgba="0.96 0.96 0.95 1"
                friction="0.330 0.383 0.001"
            />
        </body>

        <body name="b5_3" pos="0.0505 0 0.1375" >
            <joint type="free"/>

            <geom
                type="box"
                size="0.025 0.076 0.015"
                rgba="0.68 0.85 0.9 1"
                friction="0.474 0.490 0.001"
            />
        </body>

        
        <body name="b6_1" pos="0 0.0505 0.168" euler="0 0 90">
            <joint type="free"/>

            <geom
                type="box"
                size="0.025 0.076 0.015"
                rgba="0.96 0.96 0.95 1"
                friction="0.343 0.460 0.001"
            />
        </body>

        <body name="b6_2" pos="0 0 0.168" euler="0 0 90">
            <joint type="free"/>

            <geom
                type="box"
                size="0.025 0.076 0.015"
                rgba="0.68 0.85 0.9 1"
                friction="0.278 0.442 0.001"
            />
        </body>

        <body name="b6_3" pos="0 -0.0505 0.168" euler="0 0 90">
            <joint type="free"/>

            <geom
                type="box"
                size="0.025 0.076 0.015"
                rgba="0.96 0.96 0.95 1"
                friction="0.365 0.204 0.001"
            />
        </body>

        
        <body name="b7_1" pos="-0.0505 0 0.1985" >
            <joint type="free"/>

            <geom
                type="box"
                size="0.025 0.076 0.015"
                rgba="0.68 0.85 0.9 1"
                friction="0.416 0.320 0.001"
            />
        </body>

        <body name="b7_2" pos="0 0 0.1985" >
            <joint type="free"/>

            <geom
                type="box"
                size="0.025 0.076 0.015"
                rgba="0.96 0.96 0.95 1"
                friction="0.447 0.400 0.001"
            />
        </body>

        <body name="b7_3" pos="0.0505 0 0.1985" >
            <joint type="free"/>

            <geom
                type="box"
                size="0.025 0.076 0.015"
                rgba="0.68 0.85 0.9 1"
                friction="0.200 0.348 0.001"
            />
        </body>

        
        <body name="b8_1" pos="0 0.0505 0.229" euler="0 0 90">
            <joint type="free"/>

            <geom
                type="box"
                size="0.025 0.076 0.015"
                rgba="0.96 0.96 0.95 1"
                friction="0.460 0.273 0.001"
            />
        </body>

        <body name="b8_2" pos="0 0 0.229" euler="0 0 90">
            <joint type="free"/>

            <geom
                type="box"
                size="0.025 0.076 0.015"
                rgba="0.68 0.85 0.9 1"
                friction="0.298 0.461 0.001"
            />
        </body>

        <body name="b8_3" pos="0 -0.0505 0.229" euler="0 0 90">
            <joint type="free"/>

            <geom
                type="box"
                size="0.025 0.076 0.015"
                rgba="0.96 0.96 0.95 1"
                friction="0.257 0.370 0.001"
            />
        </body>

        
        <body name="b9_1" pos="-0.0505 0 0.2595" >
            <joint type="free"/>

            <geom
                type="box"
                size="0.025 0.076 0.015"
                rgba="0.68 0.85 0.9 1"
                friction="0.272 0.490 0.001"
            />
        </body>

        <body name="b9_2" pos="0 0 0.2595" >
            <joint type="free"/>

            <geom
                type="box"
                size="0.025 0.076 0.015"
                rgba="0.96 0.96 0.95 1"
                friction="0.441 0.334 0.001"
            />
        </body>

        <body name="b9_3" pos="0.0505 0 0.2595" >
            <joint type="free"/>

            <geom
                type="box"
                size="0.025 0.076 0.015"
                rgba="0.68 0.85 0.9 1"
                friction="0.224 0.296 0.001"
            />
        </body>

    </worldbody>

    <actuator>
        <motor joint="hook_slide" ctrlrange="-1 1" gear="100"/>
    </actuator>

</mujoco>
