
<mujoco model="jenga">

    <compiler angle="degree" coordinate="local"/>

    <option gravity="0 0 -9.81" timestep="0.002" iterations="200" solver="Newton" />

    <default>
        <geom density="650"
              margin="0.0005"
              gap="0.0005"
/>
    </default>

    <worldbody>
        <light diffuse=".5 .5 .5" pos="0 0 4" dir="0 0 -1"/>

        <geom
            type="plane"
            size="0.3 0.3 0.01"
            rgba="0.96 0.93 0.73 1"
            friction="0.8 0.001 0.0001"
        />

        <body name="hook" pos="0.15 0.05 0.16">
            <joint name="hook_slide" type="slide" axis="1 0 0" damping="2"/>

            <geom type="box"
                size="0.04 0.005 0.01"
                pos="0 0 0"
                rgba="0.1 0.1 0.9 1"
                density="2000"/>

            <geom type="box"
                size="0.01 0.01 0.01"
                pos="-0.05 0 0"
                rgba="1 0 0 1"
                density="2000"/>
        </body>

        <body name="hook2" pos="0.15 -0.05 0.107">
            <joint name="hook_slide2" type="slide" axis="1 0 0" damping="2"/>

            <geom type="box"
                size="0.04 0.005 0.01"
                pos="0 0 0"
                rgba="0.1 0.1 0.9 1"
                density="2000"/>

            <geom type="box"
                size="0.01 0.01 0.01"
                pos="-0.05 0 0"
                rgba="1 0 0 1"
                density="2000"/>
        </body>

        <body name="hook3" pos="0.15 0 0.107">
            <joint name="hook_slide3" type="slide" axis="1 0 0" damping="2"/>

            <geom type="box"
                size="0.04 0.005 0.01"
                pos="0 0 0"
                rgba="0.1 0.1 0.9 1"
                density="2000"/>

            <geom type="box"
                size="0.01 0.01 0.01"
                pos="-0.05 0 0"
                rgba="1 0 0 1"
                density="2000"/>
        </body>

        
        <body name="b1_1" pos="-0.0505 0 0.0155" >
            <joint type="free"/>

            <geom
                type="box"
                size="0.025 0.076 0.015"
                rgba="0.68 0.85 0.9 1"
                friction="0.461 0.048 0.0015"
            />
        </body>

        <body name="b1_2" pos="0 0 0.0155" >
            <joint type="free"/>

            <geom
                type="box"
                size="0.025 0.076 0.015"
                rgba="0.96 0.96 0.95 1"
                friction="0.355 0.023 0.0015"
            />
        </body>

        <body name="b1_3" pos="0.0505 0 0.0155" >
            <joint type="free"/>

            <geom
                type="box"
                size="0.025 0.076 0.015"
                rgba="0.68 0.85 0.9 1"
                friction="0.378 0.030 0.0015"
            />
        </body>

        
        <body name="b2_1" pos="0 0.0505 0.046" euler="0 0 90">
            <joint type="free"/>

            <geom
                type="box"
                size="0.025 0.076 0.015"
                rgba="0.96 0.96 0.95 1"
                friction="0.446 0.025 0.0015"
            />
        </body>

        <body name="b2_2" pos="0 0 0.046" euler="0 0 90">
            <joint type="free"/>

            <geom
                type="box"
                size="0.025 0.076 0.015"
                rgba="0.68 0.85 0.9 1"
                friction="0.369 0.039 0.0015"
            />
        </body>

        <body name="b2_3" pos="0 -0.0505 0.046" euler="0 0 90">
            <joint type="free"/>

            <geom
                type="box"
                size="0.025 0.076 0.015"
                rgba="0.96 0.96 0.95 1"
                friction="0.477 0.035 0.0015"
            />
        </body>

        
        <body name="b3_1" pos="-0.0505 0 0.0765" >
            <joint type="free"/>

            <geom
                type="box"
                size="0.025 0.076 0.015"
                rgba="0.68 0.85 0.9 1"
                friction="0.320 0.048 0.0015"
            />
        </body>

        <body name="b3_2" pos="0 0 0.0765" >
            <joint type="free"/>

            <geom
                type="box"
                size="0.025 0.076 0.015"
                rgba="0.96 0.96 0.95 1"
                friction="0.405 0.023 0.0015"
            />
        </body>

        <body name="b3_3" pos="0.0505 0 0.0765" >
            <joint type="free"/>

            <geom
                type="box"
                size="0.025 0.076 0.015"
                rgba="0.68 0.85 0.9 1"
                friction="0.477 0.059 0.0015"
            />
        </body>

        
        <body name="b4_1" pos="0 0.0505 0.107" euler="0 0 90">
            <joint type="free"/>

            <geom
                type="box"
                size="0.025 0.076 0.015"
                rgba="0.96 0.96 0.95 1"
                friction="0.453 0.055 0.0015"
            />
        </body>

        <body name="b4_2" pos="0 0 0.107" euler="0 0 90">
            <joint type="free"/>

            <geom
                type="box"
                size="0.025 0.076 0.015"
                rgba="0.68 0.85 0.9 1"
                friction="0.328 0.046 0.0015"
            />
        </body>

        <body name="b4_3" pos="0 -0.0505 0.107" euler="0 0 90">
            <joint type="free"/>

            <geom
                type="box"
                size="0.025 0.076 0.015"
                rgba="0.96 0.96 0.95 1"
                friction="0.475 0.044 0.0015"
            />
        </body>

        
        <body name="b5_1" pos="-0.0505 0 0.1375" >
            <joint type="free"/>

            <geom
                type="box"
                size="0.025 0.076 0.015"
                rgba="0.68 0.85 0.9 1"
                friction="0.368 0.015 0.0015"
            />
        </body>

        <body name="b5_2" pos="0 0 0.1375" >
            <joint type="free"/>

            <geom
                type="box"
                size="0.025 0.076 0.015"
                rgba="0.96 0.96 0.95 1"
                friction="0.359 0.041 0.0015"
            />
        </body>

        <body name="b5_3" pos="0.0505 0 0.1375" >
            <joint type="free"/>

            <geom
                type="box"
                size="0.025 0.076 0.015"
                rgba="0.68 0.85 0.9 1"
                friction="0.478 0.058 0.0015"
            />
        </body>

        
        <body name="b6_1" pos="0 0.0505 0.168" euler="0 0 90">
            <joint type="free"/>

            <geom
                type="box"
                size="0.025 0.076 0.015"
                rgba="0.96 0.96 0.95 1"
                friction="0.369 0.053 0.0015"
            />
        </body>

        <body name="b6_2" pos="0 0 0.168" euler="0 0 90">
            <joint type="free"/>

            <geom
                type="box"
                size="0.025 0.076 0.015"
                rgba="0.68 0.85 0.9 1"
                friction="0.315 0.050 0.0015"
            />
        </body>

        <body name="b6_3" pos="0 -0.0505 0.168" euler="0 0 90">
            <joint type="free"/>

            <geom
                type="box"
                size="0.025 0.076 0.015"
                rgba="0.96 0.96 0.95 1"
                friction="0.387 0.011 0.0015"
            />
        </body>

        
        <body name="b7_1" pos="-0.0505 0 0.1985" >
            <joint type="free"/>

            <geom
                type="box"
                size="0.025 0.076 0.015"
                rgba="0.68 0.85 0.9 1"
                friction="0.430 0.030 0.0015"
            />
        </body>

        <body name="b7_2" pos="0 0 0.1985" >
            <joint type="free"/>

            <geom
                type="box"
                size="0.025 0.076 0.015"
                rgba="0.96 0.96 0.95 1"
                friction="0.456 0.043 0.0015"
            />
        </body>

        <body name="b7_3" pos="0.0505 0 0.1985" >
            <joint type="free"/>

            <geom
                type="box"
                size="0.025 0.076 0.015"
                rgba="0.68 0.85 0.9 1"
                friction="0.250 0.035 0.0015"
            />
        </body>

        
        <body name="b8_1" pos="0 0.0505 0.229" euler="0 0 90">
            <joint type="free"/>

            <geom
                type="box"
                size="0.025 0.076 0.015"
                rgba="0.96 0.96 0.95 1"
                friction="0.467 0.022 0.0015"
            />
        </body>

        <body name="b8_2" pos="0 0 0.229" euler="0 0 90">
            <joint type="free"/>

            <geom
                type="box"
                size="0.025 0.076 0.015"
                rgba="0.68 0.85 0.9 1"
                friction="0.331 0.054 0.0015"
            />
        </body>

        <body name="b8_3" pos="0 -0.0505 0.229" euler="0 0 90">
            <joint type="free"/>

            <geom
                type="box"
                size="0.025 0.076 0.015"
                rgba="0.96 0.96 0.95 1"
                friction="0.298 0.038 0.0015"
            />
        </body>

        
        <body name="b9_1" pos="-0.0505 0 0.2595" >
            <joint type="free"/>

            <geom
                type="box"
                size="0.025 0.076 0.015"
                rgba="0.68 0.85 0.9 1"
                friction="0.310 0.058 0.0015"
            />
        </body>

        <body name="b9_2" pos="0 0 0.2595" >
            <joint type="free"/>

            <geom
                type="box"
                size="0.025 0.076 0.015"
                rgba="0.96 0.96 0.95 1"
                friction="0.451 0.032 0.0015"
            />
        </body>

        <body name="b9_3" pos="0.0505 0 0.2595" >
            <joint type="free"/>

            <geom
                type="box"
                size="0.025 0.076 0.015"
                rgba="0.68 0.85 0.9 1"
                friction="0.270 0.026 0.0015"
            />
        </body>

    </worldbody>

    <actuator>
        <motor joint="hook_slide" ctrlrange="-1 1" gear="5"/>
        <motor joint="hook_slide2" ctrlrange="-1 1" gear="5"/>
        <motor joint="hook_slide3" ctrlrange="-1 1" gear="5"/>
    </actuator>

</mujoco>
